[2023-09-02T07:58:21.044+0000] {logging_mixin.py:151} INFO - Changing /opt/***/logs/dag_id=dag_with_postgres_operator_v01/run_id=scheduled__2023-09-01T00:00:00+00:00/task_id=create_postgres_table permission to 509
[2023-09-02T07:58:21.045+0000] {logging_mixin.py:151} INFO - Failed to change /opt/***/logs/dag_id=dag_with_postgres_operator_v01/run_id=scheduled__2023-09-01T00:00:00+00:00/task_id=create_postgres_table permission to 509: [Errno 1] Operation not permitted: '/opt/***/logs/dag_id=dag_with_postgres_operator_v01/run_id=scheduled__2023-09-01T00:00:00+00:00/task_id=create_postgres_table'
[2023-09-02T07:58:21.107+0000] {logging_mixin.py:151} INFO - Changing /opt/***/logs/dag_id=dag_with_postgres_operator_v01/run_id=scheduled__2023-09-01T00:00:00+00:00/task_id=create_postgres_table permission to 509
[2023-09-02T07:58:21.109+0000] {logging_mixin.py:151} INFO - Failed to change /opt/***/logs/dag_id=dag_with_postgres_operator_v01/run_id=scheduled__2023-09-01T00:00:00+00:00/task_id=create_postgres_table permission to 509: [Errno 1] Operation not permitted: '/opt/***/logs/dag_id=dag_with_postgres_operator_v01/run_id=scheduled__2023-09-01T00:00:00+00:00/task_id=create_postgres_table'
[2023-09-02T07:58:21.199+0000] {taskinstance.py:1159} INFO - Dependencies all met for dep_context=non-requeueable deps ti=<TaskInstance: dag_with_postgres_operator_v01.create_postgres_table scheduled__2023-09-01T00:00:00+00:00 [queued]>
[2023-09-02T07:58:21.225+0000] {taskinstance.py:1159} INFO - Dependencies all met for dep_context=requeueable deps ti=<TaskInstance: dag_with_postgres_operator_v01.create_postgres_table scheduled__2023-09-01T00:00:00+00:00 [queued]>
[2023-09-02T07:58:21.226+0000] {taskinstance.py:1361} INFO - Starting attempt 1 of 6
[2023-09-02T07:58:21.275+0000] {taskinstance.py:1382} INFO - Executing <Task(PostgresOperator): create_postgres_table> on 2023-09-01 00:00:00+00:00
[2023-09-02T07:58:21.287+0000] {standard_task_runner.py:57} INFO - Started process 182 to run task
[2023-09-02T07:58:21.294+0000] {standard_task_runner.py:84} INFO - Running: ['***', 'tasks', 'run', 'dag_with_postgres_operator_v01', 'create_postgres_table', 'scheduled__2023-09-01T00:00:00+00:00', '--job-id', '29', '--raw', '--subdir', 'DAGS_FOLDER/dag-postgres-operator.py', '--cfg-path', '/tmp/tmpabt4ueou']
[2023-09-02T07:58:21.302+0000] {standard_task_runner.py:85} INFO - Job 29: Subtask create_postgres_table
[2023-09-02T07:58:21.433+0000] {logging_mixin.py:151} INFO - Changing /opt/***/logs/dag_id=dag_with_postgres_operator_v01/run_id=scheduled__2023-09-01T00:00:00+00:00/task_id=create_postgres_table permission to 509
[2023-09-02T07:58:21.435+0000] {logging_mixin.py:151} INFO - Failed to change /opt/***/logs/dag_id=dag_with_postgres_operator_v01/run_id=scheduled__2023-09-01T00:00:00+00:00/task_id=create_postgres_table permission to 509: [Errno 1] Operation not permitted: '/opt/***/logs/dag_id=dag_with_postgres_operator_v01/run_id=scheduled__2023-09-01T00:00:00+00:00/task_id=create_postgres_table'
[2023-09-02T07:58:21.440+0000] {task_command.py:415} INFO - Running <TaskInstance: dag_with_postgres_operator_v01.create_postgres_table scheduled__2023-09-01T00:00:00+00:00 [running]> on host 6c82fec646db
[2023-09-02T07:58:21.665+0000] {taskinstance.py:1660} INFO - Exporting env vars: AIRFLOW_CTX_DAG_OWNER='qpsss' AIRFLOW_CTX_DAG_ID='dag_with_postgres_operator_v01' AIRFLOW_CTX_TASK_ID='create_postgres_table' AIRFLOW_CTX_EXECUTION_DATE='2023-09-01T00:00:00+00:00' AIRFLOW_CTX_TRY_NUMBER='1' AIRFLOW_CTX_DAG_RUN_ID='scheduled__2023-09-01T00:00:00+00:00'
[2023-09-02T07:58:21.668+0000] {sql.py:274} INFO - Executing: 
            create table if not exist dag_runs (
                dt date,
                dag_id character varying,
                primary key (dt, datg_ig)
            )
        
[2023-09-02T07:58:21.690+0000] {base.py:73} INFO - Using connection ID 'postgres_localhost' for task execution.
[2023-09-02T07:58:21.716+0000] {base.py:73} INFO - Using connection ID 'postgres_localhost' for task execution.
[2023-09-02T07:58:21.814+0000] {taskinstance.py:1943} ERROR - Task failed with exception
Traceback (most recent call last):
  File "/home/airflow/.local/lib/python3.8/site-packages/airflow/providers/common/sql/operators/sql.py", line 280, in execute
    output = hook.run(
  File "/home/airflow/.local/lib/python3.8/site-packages/airflow/providers/common/sql/hooks/sql.py", line 385, in run
    with closing(self.get_conn()) as conn:
  File "/home/airflow/.local/lib/python3.8/site-packages/airflow/providers/postgres/hooks/postgres.py", line 154, in get_conn
    self.conn = psycopg2.connect(**conn_args)
  File "/home/airflow/.local/lib/python3.8/site-packages/psycopg2/__init__.py", line 122, in connect
    conn = _connect(dsn, connection_factory=connection_factory, **kwasync)
psycopg2.OperationalError: could not translate host name "localhost.docker.local" to address: Name or service not known

[2023-09-02T07:58:21.835+0000] {taskinstance.py:1400} INFO - Marking task as UP_FOR_RETRY. dag_id=dag_with_postgres_operator_v01, task_id=create_postgres_table, execution_date=20230901T000000, start_date=20230902T075821, end_date=20230902T075821
[2023-09-02T07:58:21.866+0000] {standard_task_runner.py:104} ERROR - Failed to execute job 29 for task create_postgres_table (could not translate host name "localhost.docker.local" to address: Name or service not known
; 182)
[2023-09-02T07:58:21.913+0000] {local_task_job_runner.py:228} INFO - Task exited with return code 1
[2023-09-02T07:58:21.935+0000] {taskinstance.py:2784} INFO - 0 downstream tasks scheduled from follow-on schedule check
[2023-09-02T08:07:47.341+0000] {logging_mixin.py:151} INFO - Changing /opt/***/logs/dag_id=dag_with_postgres_operator_v01/run_id=scheduled__2023-09-01T00:00:00+00:00/task_id=create_postgres_table permission to 509
[2023-09-02T08:07:47.343+0000] {logging_mixin.py:151} INFO - Failed to change /opt/***/logs/dag_id=dag_with_postgres_operator_v01/run_id=scheduled__2023-09-01T00:00:00+00:00/task_id=create_postgres_table permission to 509: [Errno 1] Operation not permitted: '/opt/***/logs/dag_id=dag_with_postgres_operator_v01/run_id=scheduled__2023-09-01T00:00:00+00:00/task_id=create_postgres_table'
[2023-09-02T08:07:47.377+0000] {logging_mixin.py:151} INFO - Changing /opt/***/logs/dag_id=dag_with_postgres_operator_v01/run_id=scheduled__2023-09-01T00:00:00+00:00/task_id=create_postgres_table permission to 509
[2023-09-02T08:07:47.378+0000] {logging_mixin.py:151} INFO - Failed to change /opt/***/logs/dag_id=dag_with_postgres_operator_v01/run_id=scheduled__2023-09-01T00:00:00+00:00/task_id=create_postgres_table permission to 509: [Errno 1] Operation not permitted: '/opt/***/logs/dag_id=dag_with_postgres_operator_v01/run_id=scheduled__2023-09-01T00:00:00+00:00/task_id=create_postgres_table'
[2023-09-02T08:07:47.416+0000] {taskinstance.py:1159} INFO - Dependencies all met for dep_context=non-requeueable deps ti=<TaskInstance: dag_with_postgres_operator_v01.create_postgres_table scheduled__2023-09-01T00:00:00+00:00 [queued]>
[2023-09-02T08:07:47.429+0000] {taskinstance.py:1159} INFO - Dependencies all met for dep_context=requeueable deps ti=<TaskInstance: dag_with_postgres_operator_v01.create_postgres_table scheduled__2023-09-01T00:00:00+00:00 [queued]>
[2023-09-02T08:07:47.430+0000] {taskinstance.py:1361} INFO - Starting attempt 1 of 6
[2023-09-02T08:07:47.446+0000] {taskinstance.py:1382} INFO - Executing <Task(PostgresOperator): create_postgres_table> on 2023-09-01 00:00:00+00:00
[2023-09-02T08:07:47.453+0000] {standard_task_runner.py:57} INFO - Started process 418 to run task
[2023-09-02T08:07:47.458+0000] {standard_task_runner.py:84} INFO - Running: ['***', 'tasks', 'run', 'dag_with_postgres_operator_v01', 'create_postgres_table', 'scheduled__2023-09-01T00:00:00+00:00', '--job-id', '34', '--raw', '--subdir', 'DAGS_FOLDER/dag-postgres-operator.py', '--cfg-path', '/tmp/tmp21rey4w9']
[2023-09-02T08:07:47.461+0000] {standard_task_runner.py:85} INFO - Job 34: Subtask create_postgres_table
[2023-09-02T08:07:47.522+0000] {logging_mixin.py:151} INFO - Changing /opt/***/logs/dag_id=dag_with_postgres_operator_v01/run_id=scheduled__2023-09-01T00:00:00+00:00/task_id=create_postgres_table permission to 509
[2023-09-02T08:07:47.523+0000] {logging_mixin.py:151} INFO - Failed to change /opt/***/logs/dag_id=dag_with_postgres_operator_v01/run_id=scheduled__2023-09-01T00:00:00+00:00/task_id=create_postgres_table permission to 509: [Errno 1] Operation not permitted: '/opt/***/logs/dag_id=dag_with_postgres_operator_v01/run_id=scheduled__2023-09-01T00:00:00+00:00/task_id=create_postgres_table'
[2023-09-02T08:07:47.525+0000] {task_command.py:415} INFO - Running <TaskInstance: dag_with_postgres_operator_v01.create_postgres_table scheduled__2023-09-01T00:00:00+00:00 [running]> on host 6c82fec646db
[2023-09-02T08:07:47.612+0000] {taskinstance.py:1660} INFO - Exporting env vars: AIRFLOW_CTX_DAG_OWNER='qpsss' AIRFLOW_CTX_DAG_ID='dag_with_postgres_operator_v01' AIRFLOW_CTX_TASK_ID='create_postgres_table' AIRFLOW_CTX_EXECUTION_DATE='2023-09-01T00:00:00+00:00' AIRFLOW_CTX_TRY_NUMBER='1' AIRFLOW_CTX_DAG_RUN_ID='scheduled__2023-09-01T00:00:00+00:00'
[2023-09-02T08:07:47.614+0000] {sql.py:274} INFO - Executing: 
            create table if not exist dag_runs (
                dt date,
                dag_id character varying,
                primary key (dt, datg_ig)
            )
        
[2023-09-02T08:07:47.627+0000] {base.py:73} INFO - Using connection ID 'postgres_localhost' for task execution.
[2023-09-02T08:07:47.637+0000] {base.py:73} INFO - Using connection ID 'postgres_localhost' for task execution.
[2023-09-02T08:07:47.702+0000] {taskinstance.py:1943} ERROR - Task failed with exception
Traceback (most recent call last):
  File "/home/airflow/.local/lib/python3.8/site-packages/airflow/providers/common/sql/operators/sql.py", line 280, in execute
    output = hook.run(
  File "/home/airflow/.local/lib/python3.8/site-packages/airflow/providers/common/sql/hooks/sql.py", line 385, in run
    with closing(self.get_conn()) as conn:
  File "/home/airflow/.local/lib/python3.8/site-packages/airflow/providers/postgres/hooks/postgres.py", line 154, in get_conn
    self.conn = psycopg2.connect(**conn_args)
  File "/home/airflow/.local/lib/python3.8/site-packages/psycopg2/__init__.py", line 122, in connect
    conn = _connect(dsn, connection_factory=connection_factory, **kwasync)
psycopg2.OperationalError: could not translate host name "localhost.docker.local" to address: Name or service not known

[2023-09-02T08:07:47.712+0000] {taskinstance.py:1400} INFO - Marking task as UP_FOR_RETRY. dag_id=dag_with_postgres_operator_v01, task_id=create_postgres_table, execution_date=20230901T000000, start_date=20230902T080747, end_date=20230902T080747
[2023-09-02T08:07:47.728+0000] {standard_task_runner.py:104} ERROR - Failed to execute job 34 for task create_postgres_table (could not translate host name "localhost.docker.local" to address: Name or service not known
; 418)
[2023-09-02T08:07:47.752+0000] {local_task_job_runner.py:228} INFO - Task exited with return code 1
[2023-09-02T08:07:47.770+0000] {taskinstance.py:2784} INFO - 0 downstream tasks scheduled from follow-on schedule check
[2023-09-02T08:11:54.826+0000] {logging_mixin.py:151} INFO - Changing /opt/***/logs/dag_id=dag_with_postgres_operator_v01/run_id=scheduled__2023-09-01T00:00:00+00:00/task_id=create_postgres_table permission to 509
[2023-09-02T08:11:54.833+0000] {logging_mixin.py:151} INFO - Failed to change /opt/***/logs/dag_id=dag_with_postgres_operator_v01/run_id=scheduled__2023-09-01T00:00:00+00:00/task_id=create_postgres_table permission to 509: [Errno 1] Operation not permitted: '/opt/***/logs/dag_id=dag_with_postgres_operator_v01/run_id=scheduled__2023-09-01T00:00:00+00:00/task_id=create_postgres_table'
[2023-09-02T08:11:54.866+0000] {logging_mixin.py:151} INFO - Changing /opt/***/logs/dag_id=dag_with_postgres_operator_v01/run_id=scheduled__2023-09-01T00:00:00+00:00/task_id=create_postgres_table permission to 509
[2023-09-02T08:11:54.867+0000] {logging_mixin.py:151} INFO - Failed to change /opt/***/logs/dag_id=dag_with_postgres_operator_v01/run_id=scheduled__2023-09-01T00:00:00+00:00/task_id=create_postgres_table permission to 509: [Errno 1] Operation not permitted: '/opt/***/logs/dag_id=dag_with_postgres_operator_v01/run_id=scheduled__2023-09-01T00:00:00+00:00/task_id=create_postgres_table'
[2023-09-02T08:11:54.901+0000] {taskinstance.py:1159} INFO - Dependencies all met for dep_context=non-requeueable deps ti=<TaskInstance: dag_with_postgres_operator_v01.create_postgres_table scheduled__2023-09-01T00:00:00+00:00 [queued]>
[2023-09-02T08:11:54.912+0000] {taskinstance.py:1159} INFO - Dependencies all met for dep_context=requeueable deps ti=<TaskInstance: dag_with_postgres_operator_v01.create_postgres_table scheduled__2023-09-01T00:00:00+00:00 [queued]>
[2023-09-02T08:11:54.913+0000] {taskinstance.py:1361} INFO - Starting attempt 1 of 6
[2023-09-02T08:11:54.930+0000] {taskinstance.py:1382} INFO - Executing <Task(PostgresOperator): create_postgres_table> on 2023-09-01 00:00:00+00:00
[2023-09-02T08:11:54.935+0000] {standard_task_runner.py:57} INFO - Started process 518 to run task
[2023-09-02T08:11:54.938+0000] {standard_task_runner.py:84} INFO - Running: ['***', 'tasks', 'run', 'dag_with_postgres_operator_v01', 'create_postgres_table', 'scheduled__2023-09-01T00:00:00+00:00', '--job-id', '36', '--raw', '--subdir', 'DAGS_FOLDER/dag-postgres-operator.py', '--cfg-path', '/tmp/tmp3hjml1ko']
[2023-09-02T08:11:54.940+0000] {standard_task_runner.py:85} INFO - Job 36: Subtask create_postgres_table
[2023-09-02T08:11:54.994+0000] {logging_mixin.py:151} INFO - Changing /opt/***/logs/dag_id=dag_with_postgres_operator_v01/run_id=scheduled__2023-09-01T00:00:00+00:00/task_id=create_postgres_table permission to 509
[2023-09-02T08:11:54.995+0000] {logging_mixin.py:151} INFO - Failed to change /opt/***/logs/dag_id=dag_with_postgres_operator_v01/run_id=scheduled__2023-09-01T00:00:00+00:00/task_id=create_postgres_table permission to 509: [Errno 1] Operation not permitted: '/opt/***/logs/dag_id=dag_with_postgres_operator_v01/run_id=scheduled__2023-09-01T00:00:00+00:00/task_id=create_postgres_table'
[2023-09-02T08:11:54.998+0000] {task_command.py:415} INFO - Running <TaskInstance: dag_with_postgres_operator_v01.create_postgres_table scheduled__2023-09-01T00:00:00+00:00 [running]> on host 6c82fec646db
[2023-09-02T08:11:55.083+0000] {taskinstance.py:1660} INFO - Exporting env vars: AIRFLOW_CTX_DAG_OWNER='qpsss' AIRFLOW_CTX_DAG_ID='dag_with_postgres_operator_v01' AIRFLOW_CTX_TASK_ID='create_postgres_table' AIRFLOW_CTX_EXECUTION_DATE='2023-09-01T00:00:00+00:00' AIRFLOW_CTX_TRY_NUMBER='1' AIRFLOW_CTX_DAG_RUN_ID='scheduled__2023-09-01T00:00:00+00:00'
[2023-09-02T08:11:55.084+0000] {sql.py:274} INFO - Executing: 
            create table if not exist dag_runs (
                dt date,
                dag_id character varying,
                primary key (dt, datg_ig)
            )
        
[2023-09-02T08:11:55.097+0000] {base.py:73} INFO - Using connection ID 'postgres_localhost' for task execution.
[2023-09-02T08:11:55.107+0000] {base.py:73} INFO - Using connection ID 'postgres_localhost' for task execution.
[2023-09-02T08:11:55.200+0000] {taskinstance.py:1943} ERROR - Task failed with exception
Traceback (most recent call last):
  File "/home/airflow/.local/lib/python3.8/site-packages/airflow/providers/common/sql/operators/sql.py", line 280, in execute
    output = hook.run(
  File "/home/airflow/.local/lib/python3.8/site-packages/airflow/providers/common/sql/hooks/sql.py", line 385, in run
    with closing(self.get_conn()) as conn:
  File "/home/airflow/.local/lib/python3.8/site-packages/airflow/providers/postgres/hooks/postgres.py", line 154, in get_conn
    self.conn = psycopg2.connect(**conn_args)
  File "/home/airflow/.local/lib/python3.8/site-packages/psycopg2/__init__.py", line 122, in connect
    conn = _connect(dsn, connection_factory=connection_factory, **kwasync)
psycopg2.OperationalError: could not translate host name "host.docker.local" to address: Name or service not known

[2023-09-02T08:11:55.210+0000] {taskinstance.py:1400} INFO - Marking task as UP_FOR_RETRY. dag_id=dag_with_postgres_operator_v01, task_id=create_postgres_table, execution_date=20230901T000000, start_date=20230902T081154, end_date=20230902T081155
[2023-09-02T08:11:55.225+0000] {standard_task_runner.py:104} ERROR - Failed to execute job 36 for task create_postgres_table (could not translate host name "host.docker.local" to address: Name or service not known
; 518)
[2023-09-02T08:11:55.232+0000] {local_task_job_runner.py:228} INFO - Task exited with return code 1
[2023-09-02T08:11:55.250+0000] {taskinstance.py:2784} INFO - 0 downstream tasks scheduled from follow-on schedule check
[2023-09-02T08:21:09.748+0000] {logging_mixin.py:151} INFO - Changing /opt/***/logs/dag_id=dag_with_postgres_operator_v01/run_id=scheduled__2023-09-01T00:00:00+00:00/task_id=create_postgres_table permission to 509
[2023-09-02T08:21:09.755+0000] {logging_mixin.py:151} INFO - Failed to change /opt/***/logs/dag_id=dag_with_postgres_operator_v01/run_id=scheduled__2023-09-01T00:00:00+00:00/task_id=create_postgres_table permission to 509: [Errno 1] Operation not permitted: '/opt/***/logs/dag_id=dag_with_postgres_operator_v01/run_id=scheduled__2023-09-01T00:00:00+00:00/task_id=create_postgres_table'
[2023-09-02T08:21:09.791+0000] {logging_mixin.py:151} INFO - Changing /opt/***/logs/dag_id=dag_with_postgres_operator_v01/run_id=scheduled__2023-09-01T00:00:00+00:00/task_id=create_postgres_table permission to 509
[2023-09-02T08:21:09.792+0000] {logging_mixin.py:151} INFO - Failed to change /opt/***/logs/dag_id=dag_with_postgres_operator_v01/run_id=scheduled__2023-09-01T00:00:00+00:00/task_id=create_postgres_table permission to 509: [Errno 1] Operation not permitted: '/opt/***/logs/dag_id=dag_with_postgres_operator_v01/run_id=scheduled__2023-09-01T00:00:00+00:00/task_id=create_postgres_table'
[2023-09-02T08:21:09.846+0000] {taskinstance.py:1159} INFO - Dependencies all met for dep_context=non-requeueable deps ti=<TaskInstance: dag_with_postgres_operator_v01.create_postgres_table scheduled__2023-09-01T00:00:00+00:00 [queued]>
[2023-09-02T08:21:09.860+0000] {taskinstance.py:1159} INFO - Dependencies all met for dep_context=requeueable deps ti=<TaskInstance: dag_with_postgres_operator_v01.create_postgres_table scheduled__2023-09-01T00:00:00+00:00 [queued]>
[2023-09-02T08:21:09.860+0000] {taskinstance.py:1361} INFO - Starting attempt 1 of 6
[2023-09-02T08:21:09.879+0000] {taskinstance.py:1382} INFO - Executing <Task(PostgresOperator): create_postgres_table> on 2023-09-01 00:00:00+00:00
[2023-09-02T08:21:09.888+0000] {standard_task_runner.py:57} INFO - Started process 749 to run task
[2023-09-02T08:21:09.894+0000] {standard_task_runner.py:84} INFO - Running: ['***', 'tasks', 'run', 'dag_with_postgres_operator_v01', 'create_postgres_table', 'scheduled__2023-09-01T00:00:00+00:00', '--job-id', '40', '--raw', '--subdir', 'DAGS_FOLDER/dag-postgres-operator.py', '--cfg-path', '/tmp/tmpf_ncqa8f']
[2023-09-02T08:21:09.899+0000] {standard_task_runner.py:85} INFO - Job 40: Subtask create_postgres_table
[2023-09-02T08:21:09.965+0000] {logging_mixin.py:151} INFO - Changing /opt/***/logs/dag_id=dag_with_postgres_operator_v01/run_id=scheduled__2023-09-01T00:00:00+00:00/task_id=create_postgres_table permission to 509
[2023-09-02T08:21:09.966+0000] {logging_mixin.py:151} INFO - Failed to change /opt/***/logs/dag_id=dag_with_postgres_operator_v01/run_id=scheduled__2023-09-01T00:00:00+00:00/task_id=create_postgres_table permission to 509: [Errno 1] Operation not permitted: '/opt/***/logs/dag_id=dag_with_postgres_operator_v01/run_id=scheduled__2023-09-01T00:00:00+00:00/task_id=create_postgres_table'
[2023-09-02T08:21:09.969+0000] {task_command.py:415} INFO - Running <TaskInstance: dag_with_postgres_operator_v01.create_postgres_table scheduled__2023-09-01T00:00:00+00:00 [running]> on host 6c82fec646db
[2023-09-02T08:21:10.057+0000] {taskinstance.py:1660} INFO - Exporting env vars: AIRFLOW_CTX_DAG_OWNER='qpsss' AIRFLOW_CTX_DAG_ID='dag_with_postgres_operator_v01' AIRFLOW_CTX_TASK_ID='create_postgres_table' AIRFLOW_CTX_EXECUTION_DATE='2023-09-01T00:00:00+00:00' AIRFLOW_CTX_TRY_NUMBER='1' AIRFLOW_CTX_DAG_RUN_ID='scheduled__2023-09-01T00:00:00+00:00'
[2023-09-02T08:21:10.059+0000] {sql.py:274} INFO - Executing: 
            create table if not exist dag_runs (
                dt date,
                dag_id character varying,
                primary key (dt, datg_ig)
            )
        
[2023-09-02T08:21:10.071+0000] {base.py:73} INFO - Using connection ID 'postgres_localhost' for task execution.
[2023-09-02T08:21:10.081+0000] {base.py:73} INFO - Using connection ID 'postgres_localhost' for task execution.
[2023-09-02T08:21:10.087+0000] {sql.py:418} INFO - Running statement: 
            create table if not exist dag_runs (
                dt date,
                dag_id character varying,
                primary key (dt, datg_ig)
            )
        , parameters: None
[2023-09-02T08:21:10.089+0000] {taskinstance.py:1943} ERROR - Task failed with exception
Traceback (most recent call last):
  File "/home/airflow/.local/lib/python3.8/site-packages/airflow/providers/common/sql/operators/sql.py", line 280, in execute
    output = hook.run(
  File "/home/airflow/.local/lib/python3.8/site-packages/airflow/providers/common/sql/hooks/sql.py", line 392, in run
    self._run_command(cur, sql_statement, parameters)
  File "/home/airflow/.local/lib/python3.8/site-packages/airflow/providers/common/sql/hooks/sql.py", line 423, in _run_command
    cur.execute(sql_statement)
psycopg2.errors.SyntaxError: syntax error at or near "exist"
LINE 2:             create table if not exist dag_runs (
                                        ^

[2023-09-02T08:21:10.100+0000] {taskinstance.py:1400} INFO - Marking task as UP_FOR_RETRY. dag_id=dag_with_postgres_operator_v01, task_id=create_postgres_table, execution_date=20230901T000000, start_date=20230902T082109, end_date=20230902T082110
[2023-09-02T08:21:10.117+0000] {standard_task_runner.py:104} ERROR - Failed to execute job 40 for task create_postgres_table (syntax error at or near "exist"
LINE 2:             create table if not exist dag_runs (
                                        ^
; 749)
[2023-09-02T08:21:10.149+0000] {local_task_job_runner.py:228} INFO - Task exited with return code 1
[2023-09-02T08:21:10.168+0000] {taskinstance.py:2784} INFO - 0 downstream tasks scheduled from follow-on schedule check
[2023-09-02T08:29:17.705+0000] {logging_mixin.py:151} INFO - Changing /opt/***/logs/dag_id=dag_with_postgres_operator_v01/run_id=scheduled__2023-09-01T00:00:00+00:00/task_id=create_postgres_table permission to 509
[2023-09-02T08:29:17.711+0000] {logging_mixin.py:151} INFO - Failed to change /opt/***/logs/dag_id=dag_with_postgres_operator_v01/run_id=scheduled__2023-09-01T00:00:00+00:00/task_id=create_postgres_table permission to 509: [Errno 1] Operation not permitted: '/opt/***/logs/dag_id=dag_with_postgres_operator_v01/run_id=scheduled__2023-09-01T00:00:00+00:00/task_id=create_postgres_table'
[2023-09-02T08:29:17.743+0000] {logging_mixin.py:151} INFO - Changing /opt/***/logs/dag_id=dag_with_postgres_operator_v01/run_id=scheduled__2023-09-01T00:00:00+00:00/task_id=create_postgres_table permission to 509
[2023-09-02T08:29:17.744+0000] {logging_mixin.py:151} INFO - Failed to change /opt/***/logs/dag_id=dag_with_postgres_operator_v01/run_id=scheduled__2023-09-01T00:00:00+00:00/task_id=create_postgres_table permission to 509: [Errno 1] Operation not permitted: '/opt/***/logs/dag_id=dag_with_postgres_operator_v01/run_id=scheduled__2023-09-01T00:00:00+00:00/task_id=create_postgres_table'
[2023-09-02T08:29:17.781+0000] {taskinstance.py:1159} INFO - Dependencies all met for dep_context=non-requeueable deps ti=<TaskInstance: dag_with_postgres_operator_v01.create_postgres_table scheduled__2023-09-01T00:00:00+00:00 [queued]>
[2023-09-02T08:29:17.792+0000] {taskinstance.py:1159} INFO - Dependencies all met for dep_context=requeueable deps ti=<TaskInstance: dag_with_postgres_operator_v01.create_postgres_table scheduled__2023-09-01T00:00:00+00:00 [queued]>
[2023-09-02T08:29:17.793+0000] {taskinstance.py:1361} INFO - Starting attempt 1 of 6
[2023-09-02T08:29:17.810+0000] {taskinstance.py:1382} INFO - Executing <Task(PostgresOperator): create_postgres_table> on 2023-09-01 00:00:00+00:00
[2023-09-02T08:29:17.815+0000] {standard_task_runner.py:57} INFO - Started process 961 to run task
[2023-09-02T08:29:17.819+0000] {standard_task_runner.py:84} INFO - Running: ['***', 'tasks', 'run', 'dag_with_postgres_operator_v01', 'create_postgres_table', 'scheduled__2023-09-01T00:00:00+00:00', '--job-id', '46', '--raw', '--subdir', 'DAGS_FOLDER/dag-postgres-operator.py', '--cfg-path', '/tmp/tmptops0h7a']
[2023-09-02T08:29:17.823+0000] {standard_task_runner.py:85} INFO - Job 46: Subtask create_postgres_table
[2023-09-02T08:29:17.881+0000] {logging_mixin.py:151} INFO - Changing /opt/***/logs/dag_id=dag_with_postgres_operator_v01/run_id=scheduled__2023-09-01T00:00:00+00:00/task_id=create_postgres_table permission to 509
[2023-09-02T08:29:17.882+0000] {logging_mixin.py:151} INFO - Failed to change /opt/***/logs/dag_id=dag_with_postgres_operator_v01/run_id=scheduled__2023-09-01T00:00:00+00:00/task_id=create_postgres_table permission to 509: [Errno 1] Operation not permitted: '/opt/***/logs/dag_id=dag_with_postgres_operator_v01/run_id=scheduled__2023-09-01T00:00:00+00:00/task_id=create_postgres_table'
[2023-09-02T08:29:17.885+0000] {task_command.py:415} INFO - Running <TaskInstance: dag_with_postgres_operator_v01.create_postgres_table scheduled__2023-09-01T00:00:00+00:00 [running]> on host 6c82fec646db
[2023-09-02T08:29:17.971+0000] {taskinstance.py:1660} INFO - Exporting env vars: AIRFLOW_CTX_DAG_OWNER='qpsss' AIRFLOW_CTX_DAG_ID='dag_with_postgres_operator_v01' AIRFLOW_CTX_TASK_ID='create_postgres_table' AIRFLOW_CTX_EXECUTION_DATE='2023-09-01T00:00:00+00:00' AIRFLOW_CTX_TRY_NUMBER='1' AIRFLOW_CTX_DAG_RUN_ID='scheduled__2023-09-01T00:00:00+00:00'
[2023-09-02T08:29:17.973+0000] {sql.py:274} INFO - Executing: 
            create table if not exist dag_runs (
                dt date,
                dag_id character varying,
                primary key (dt, datg_ig)
            )
        
[2023-09-02T08:29:17.994+0000] {taskinstance.py:1943} ERROR - Task failed with exception
Traceback (most recent call last):
  File "/home/airflow/.local/lib/python3.8/site-packages/airflow/providers/common/sql/operators/sql.py", line 275, in execute
    hook = self.get_db_hook()
  File "/home/airflow/.local/lib/python3.8/site-packages/airflow/providers/common/sql/operators/sql.py", line 186, in get_db_hook
    return self._hook
  File "/usr/local/lib/python3.8/functools.py", line 967, in __get__
    val = self.func(instance)
  File "/home/airflow/.local/lib/python3.8/site-packages/airflow/providers/common/sql/operators/sql.py", line 148, in _hook
    conn = BaseHook.get_connection(conn_id)
  File "/home/airflow/.local/lib/python3.8/site-packages/airflow/hooks/base.py", line 72, in get_connection
    conn = Connection.get_connection_from_secrets(conn_id)
  File "/home/airflow/.local/lib/python3.8/site-packages/airflow/models/connection.py", line 477, in get_connection_from_secrets
    raise AirflowNotFoundException(f"The conn_id `{conn_id}` isn't defined")
airflow.exceptions.AirflowNotFoundException: The conn_id `postgres_localhost` isn't defined
[2023-09-02T08:29:18.001+0000] {taskinstance.py:1400} INFO - Marking task as UP_FOR_RETRY. dag_id=dag_with_postgres_operator_v01, task_id=create_postgres_table, execution_date=20230901T000000, start_date=20230902T082917, end_date=20230902T082918
[2023-09-02T08:29:18.016+0000] {standard_task_runner.py:104} ERROR - Failed to execute job 46 for task create_postgres_table (The conn_id `postgres_localhost` isn't defined; 961)
[2023-09-02T08:29:18.034+0000] {local_task_job_runner.py:228} INFO - Task exited with return code 1
[2023-09-02T08:29:18.053+0000] {taskinstance.py:2784} INFO - 0 downstream tasks scheduled from follow-on schedule check
[2023-09-02T08:33:02.114+0000] {logging_mixin.py:151} INFO - Changing /opt/***/logs/dag_id=dag_with_postgres_operator_v01/run_id=scheduled__2023-09-01T00:00:00+00:00/task_id=create_postgres_table permission to 509
[2023-09-02T08:33:02.116+0000] {logging_mixin.py:151} INFO - Failed to change /opt/***/logs/dag_id=dag_with_postgres_operator_v01/run_id=scheduled__2023-09-01T00:00:00+00:00/task_id=create_postgres_table permission to 509: [Errno 1] Operation not permitted: '/opt/***/logs/dag_id=dag_with_postgres_operator_v01/run_id=scheduled__2023-09-01T00:00:00+00:00/task_id=create_postgres_table'
[2023-09-02T08:33:02.149+0000] {logging_mixin.py:151} INFO - Changing /opt/***/logs/dag_id=dag_with_postgres_operator_v01/run_id=scheduled__2023-09-01T00:00:00+00:00/task_id=create_postgres_table permission to 509
[2023-09-02T08:33:02.150+0000] {logging_mixin.py:151} INFO - Failed to change /opt/***/logs/dag_id=dag_with_postgres_operator_v01/run_id=scheduled__2023-09-01T00:00:00+00:00/task_id=create_postgres_table permission to 509: [Errno 1] Operation not permitted: '/opt/***/logs/dag_id=dag_with_postgres_operator_v01/run_id=scheduled__2023-09-01T00:00:00+00:00/task_id=create_postgres_table'
[2023-09-02T08:33:02.191+0000] {taskinstance.py:1159} INFO - Dependencies all met for dep_context=non-requeueable deps ti=<TaskInstance: dag_with_postgres_operator_v01.create_postgres_table scheduled__2023-09-01T00:00:00+00:00 [queued]>
[2023-09-02T08:33:02.203+0000] {taskinstance.py:1159} INFO - Dependencies all met for dep_context=requeueable deps ti=<TaskInstance: dag_with_postgres_operator_v01.create_postgres_table scheduled__2023-09-01T00:00:00+00:00 [queued]>
[2023-09-02T08:33:02.204+0000] {taskinstance.py:1361} INFO - Starting attempt 1 of 6
[2023-09-02T08:33:02.220+0000] {taskinstance.py:1382} INFO - Executing <Task(PostgresOperator): create_postgres_table> on 2023-09-01 00:00:00+00:00
[2023-09-02T08:33:02.225+0000] {standard_task_runner.py:57} INFO - Started process 1049 to run task
[2023-09-02T08:33:02.228+0000] {standard_task_runner.py:84} INFO - Running: ['***', 'tasks', 'run', 'dag_with_postgres_operator_v01', 'create_postgres_table', 'scheduled__2023-09-01T00:00:00+00:00', '--job-id', '48', '--raw', '--subdir', 'DAGS_FOLDER/dag-postgres-operator.py', '--cfg-path', '/tmp/tmpbwtgapx2']
[2023-09-02T08:33:02.231+0000] {standard_task_runner.py:85} INFO - Job 48: Subtask create_postgres_table
[2023-09-02T08:33:02.294+0000] {logging_mixin.py:151} INFO - Changing /opt/***/logs/dag_id=dag_with_postgres_operator_v01/run_id=scheduled__2023-09-01T00:00:00+00:00/task_id=create_postgres_table permission to 509
[2023-09-02T08:33:02.295+0000] {logging_mixin.py:151} INFO - Failed to change /opt/***/logs/dag_id=dag_with_postgres_operator_v01/run_id=scheduled__2023-09-01T00:00:00+00:00/task_id=create_postgres_table permission to 509: [Errno 1] Operation not permitted: '/opt/***/logs/dag_id=dag_with_postgres_operator_v01/run_id=scheduled__2023-09-01T00:00:00+00:00/task_id=create_postgres_table'
[2023-09-02T08:33:02.297+0000] {task_command.py:415} INFO - Running <TaskInstance: dag_with_postgres_operator_v01.create_postgres_table scheduled__2023-09-01T00:00:00+00:00 [running]> on host 6c82fec646db
[2023-09-02T08:33:02.384+0000] {taskinstance.py:1660} INFO - Exporting env vars: AIRFLOW_CTX_DAG_OWNER='qpsss' AIRFLOW_CTX_DAG_ID='dag_with_postgres_operator_v01' AIRFLOW_CTX_TASK_ID='create_postgres_table' AIRFLOW_CTX_EXECUTION_DATE='2023-09-01T00:00:00+00:00' AIRFLOW_CTX_TRY_NUMBER='1' AIRFLOW_CTX_DAG_RUN_ID='scheduled__2023-09-01T00:00:00+00:00'
[2023-09-02T08:33:02.386+0000] {sql.py:274} INFO - Executing: 
            create table if not exist dag_runs (
                dt date,
                dag_id character varying,
                primary key (dt, datg_ig)
            )
        
[2023-09-02T08:33:02.399+0000] {base.py:73} INFO - Using connection ID 'postgres_localhost' for task execution.
[2023-09-02T08:33:02.411+0000] {base.py:73} INFO - Using connection ID 'postgres_localhost' for task execution.
[2023-09-02T08:33:02.417+0000] {sql.py:418} INFO - Running statement: 
            create table if not exist dag_runs (
                dt date,
                dag_id character varying,
                primary key (dt, datg_ig)
            )
        , parameters: None
[2023-09-02T08:33:02.419+0000] {taskinstance.py:1943} ERROR - Task failed with exception
Traceback (most recent call last):
  File "/home/airflow/.local/lib/python3.8/site-packages/airflow/providers/common/sql/operators/sql.py", line 280, in execute
    output = hook.run(
  File "/home/airflow/.local/lib/python3.8/site-packages/airflow/providers/common/sql/hooks/sql.py", line 392, in run
    self._run_command(cur, sql_statement, parameters)
  File "/home/airflow/.local/lib/python3.8/site-packages/airflow/providers/common/sql/hooks/sql.py", line 423, in _run_command
    cur.execute(sql_statement)
psycopg2.errors.SyntaxError: syntax error at or near "exist"
LINE 2:             create table if not exist dag_runs (
                                        ^

[2023-09-02T08:33:02.430+0000] {taskinstance.py:1400} INFO - Marking task as UP_FOR_RETRY. dag_id=dag_with_postgres_operator_v01, task_id=create_postgres_table, execution_date=20230901T000000, start_date=20230902T083302, end_date=20230902T083302
[2023-09-02T08:33:02.444+0000] {standard_task_runner.py:104} ERROR - Failed to execute job 48 for task create_postgres_table (syntax error at or near "exist"
LINE 2:             create table if not exist dag_runs (
                                        ^
; 1049)
[2023-09-02T08:33:02.483+0000] {local_task_job_runner.py:228} INFO - Task exited with return code 1
[2023-09-02T08:33:02.501+0000] {taskinstance.py:2784} INFO - 0 downstream tasks scheduled from follow-on schedule check
[2023-09-02T08:39:01.818+0000] {logging_mixin.py:151} INFO - Changing /opt/***/logs/dag_id=dag_with_postgres_operator_v01/run_id=scheduled__2023-09-01T00:00:00+00:00/task_id=create_postgres_table permission to 509
[2023-09-02T08:39:01.819+0000] {logging_mixin.py:151} INFO - Failed to change /opt/***/logs/dag_id=dag_with_postgres_operator_v01/run_id=scheduled__2023-09-01T00:00:00+00:00/task_id=create_postgres_table permission to 509: [Errno 1] Operation not permitted: '/opt/***/logs/dag_id=dag_with_postgres_operator_v01/run_id=scheduled__2023-09-01T00:00:00+00:00/task_id=create_postgres_table'
[2023-09-02T08:39:01.856+0000] {logging_mixin.py:151} INFO - Changing /opt/***/logs/dag_id=dag_with_postgres_operator_v01/run_id=scheduled__2023-09-01T00:00:00+00:00/task_id=create_postgres_table permission to 509
[2023-09-02T08:39:01.857+0000] {logging_mixin.py:151} INFO - Failed to change /opt/***/logs/dag_id=dag_with_postgres_operator_v01/run_id=scheduled__2023-09-01T00:00:00+00:00/task_id=create_postgres_table permission to 509: [Errno 1] Operation not permitted: '/opt/***/logs/dag_id=dag_with_postgres_operator_v01/run_id=scheduled__2023-09-01T00:00:00+00:00/task_id=create_postgres_table'
[2023-09-02T08:39:01.900+0000] {taskinstance.py:1159} INFO - Dependencies all met for dep_context=non-requeueable deps ti=<TaskInstance: dag_with_postgres_operator_v01.create_postgres_table scheduled__2023-09-01T00:00:00+00:00 [queued]>
[2023-09-02T08:39:01.913+0000] {taskinstance.py:1159} INFO - Dependencies all met for dep_context=requeueable deps ti=<TaskInstance: dag_with_postgres_operator_v01.create_postgres_table scheduled__2023-09-01T00:00:00+00:00 [queued]>
[2023-09-02T08:39:01.914+0000] {taskinstance.py:1361} INFO - Starting attempt 1 of 6
[2023-09-02T08:39:01.931+0000] {taskinstance.py:1382} INFO - Executing <Task(PostgresOperator): create_postgres_table> on 2023-09-01 00:00:00+00:00
[2023-09-02T08:39:01.937+0000] {standard_task_runner.py:57} INFO - Started process 278 to run task
[2023-09-02T08:39:01.942+0000] {standard_task_runner.py:84} INFO - Running: ['***', 'tasks', 'run', 'dag_with_postgres_operator_v01', 'create_postgres_table', 'scheduled__2023-09-01T00:00:00+00:00', '--job-id', '57', '--raw', '--subdir', 'DAGS_FOLDER/dag-postgres-operator.py', '--cfg-path', '/tmp/tmpqj_onb91']
[2023-09-02T08:39:01.945+0000] {standard_task_runner.py:85} INFO - Job 57: Subtask create_postgres_table
[2023-09-02T08:39:02.004+0000] {logging_mixin.py:151} INFO - Changing /opt/***/logs/dag_id=dag_with_postgres_operator_v01/run_id=scheduled__2023-09-01T00:00:00+00:00/task_id=create_postgres_table permission to 509
[2023-09-02T08:39:02.005+0000] {logging_mixin.py:151} INFO - Failed to change /opt/***/logs/dag_id=dag_with_postgres_operator_v01/run_id=scheduled__2023-09-01T00:00:00+00:00/task_id=create_postgres_table permission to 509: [Errno 1] Operation not permitted: '/opt/***/logs/dag_id=dag_with_postgres_operator_v01/run_id=scheduled__2023-09-01T00:00:00+00:00/task_id=create_postgres_table'
[2023-09-02T08:39:02.009+0000] {task_command.py:415} INFO - Running <TaskInstance: dag_with_postgres_operator_v01.create_postgres_table scheduled__2023-09-01T00:00:00+00:00 [running]> on host 6c82fec646db
[2023-09-02T08:39:02.110+0000] {taskinstance.py:1660} INFO - Exporting env vars: AIRFLOW_CTX_DAG_OWNER='qpsss' AIRFLOW_CTX_DAG_ID='dag_with_postgres_operator_v01' AIRFLOW_CTX_TASK_ID='create_postgres_table' AIRFLOW_CTX_EXECUTION_DATE='2023-09-01T00:00:00+00:00' AIRFLOW_CTX_TRY_NUMBER='1' AIRFLOW_CTX_DAG_RUN_ID='scheduled__2023-09-01T00:00:00+00:00'
[2023-09-02T08:39:02.111+0000] {sql.py:274} INFO - Executing: 
            create table if not exists dag_runs (
                dt date,
                dag_id character varying,
                primary key (dt, datg_ig)
            )
        
[2023-09-02T08:39:02.123+0000] {base.py:73} INFO - Using connection ID 'postgres_localhost' for task execution.
[2023-09-02T08:39:02.132+0000] {base.py:73} INFO - Using connection ID 'postgres_localhost' for task execution.
[2023-09-02T08:39:02.137+0000] {sql.py:418} INFO - Running statement: 
            create table if not exists dag_runs (
                dt date,
                dag_id character varying,
                primary key (dt, datg_ig)
            )
        , parameters: None
[2023-09-02T08:39:02.140+0000] {taskinstance.py:1943} ERROR - Task failed with exception
Traceback (most recent call last):
  File "/home/airflow/.local/lib/python3.8/site-packages/airflow/providers/common/sql/operators/sql.py", line 280, in execute
    output = hook.run(
  File "/home/airflow/.local/lib/python3.8/site-packages/airflow/providers/common/sql/hooks/sql.py", line 392, in run
    self._run_command(cur, sql_statement, parameters)
  File "/home/airflow/.local/lib/python3.8/site-packages/airflow/providers/common/sql/hooks/sql.py", line 423, in _run_command
    cur.execute(sql_statement)
psycopg2.errors.UndefinedColumn: column "datg_ig" named in key does not exist
LINE 5:                 primary key (dt, datg_ig)
                        ^

[2023-09-02T08:39:02.150+0000] {taskinstance.py:1400} INFO - Marking task as UP_FOR_RETRY. dag_id=dag_with_postgres_operator_v01, task_id=create_postgres_table, execution_date=20230901T000000, start_date=20230902T083901, end_date=20230902T083902
[2023-09-02T08:39:02.168+0000] {standard_task_runner.py:104} ERROR - Failed to execute job 57 for task create_postgres_table (column "datg_ig" named in key does not exist
LINE 5:                 primary key (dt, datg_ig)
                        ^
; 278)
[2023-09-02T08:39:02.195+0000] {local_task_job_runner.py:228} INFO - Task exited with return code 1
[2023-09-02T08:39:02.217+0000] {taskinstance.py:2784} INFO - 0 downstream tasks scheduled from follow-on schedule check
