[2023-09-03T05:00:44.057+0000] {logging_mixin.py:151} INFO - Changing /opt/***/logs/dag_id=dag_with_postgres_operator_v02/run_id=scheduled__2023-09-02T00:00:00+00:00/task_id=insert_into_table permission to 509
[2023-09-03T05:00:44.058+0000] {logging_mixin.py:151} INFO - Failed to change /opt/***/logs/dag_id=dag_with_postgres_operator_v02/run_id=scheduled__2023-09-02T00:00:00+00:00/task_id=insert_into_table permission to 509: [Errno 1] Operation not permitted: '/opt/***/logs/dag_id=dag_with_postgres_operator_v02/run_id=scheduled__2023-09-02T00:00:00+00:00/task_id=insert_into_table'
[2023-09-03T05:00:44.096+0000] {logging_mixin.py:151} INFO - Changing /opt/***/logs/dag_id=dag_with_postgres_operator_v02/run_id=scheduled__2023-09-02T00:00:00+00:00/task_id=insert_into_table permission to 509
[2023-09-03T05:00:44.097+0000] {logging_mixin.py:151} INFO - Failed to change /opt/***/logs/dag_id=dag_with_postgres_operator_v02/run_id=scheduled__2023-09-02T00:00:00+00:00/task_id=insert_into_table permission to 509: [Errno 1] Operation not permitted: '/opt/***/logs/dag_id=dag_with_postgres_operator_v02/run_id=scheduled__2023-09-02T00:00:00+00:00/task_id=insert_into_table'
[2023-09-03T05:00:44.142+0000] {taskinstance.py:1159} INFO - Dependencies all met for dep_context=non-requeueable deps ti=<TaskInstance: dag_with_postgres_operator_v02.insert_into_table scheduled__2023-09-02T00:00:00+00:00 [queued]>
[2023-09-03T05:00:44.156+0000] {taskinstance.py:1159} INFO - Dependencies all met for dep_context=requeueable deps ti=<TaskInstance: dag_with_postgres_operator_v02.insert_into_table scheduled__2023-09-02T00:00:00+00:00 [queued]>
[2023-09-03T05:00:44.156+0000] {taskinstance.py:1361} INFO - Starting attempt 1 of 6
[2023-09-03T05:00:44.176+0000] {taskinstance.py:1382} INFO - Executing <Task(PostgresOperator): insert_into_table> on 2023-09-02 00:00:00+00:00
[2023-09-03T05:00:44.188+0000] {standard_task_runner.py:84} INFO - Running: ['***', 'tasks', 'run', 'dag_with_postgres_operator_v02', 'insert_into_table', 'scheduled__2023-09-02T00:00:00+00:00', '--job-id', '72', '--raw', '--subdir', 'DAGS_FOLDER/dag-postgres-operator.py', '--cfg-path', '/tmp/tmpw2xo4cv5']
[2023-09-03T05:00:44.186+0000] {standard_task_runner.py:57} INFO - Started process 10451 to run task
[2023-09-03T05:00:44.191+0000] {standard_task_runner.py:85} INFO - Job 72: Subtask insert_into_table
[2023-09-03T05:00:44.248+0000] {logging_mixin.py:151} INFO - Changing /opt/***/logs/dag_id=dag_with_postgres_operator_v02/run_id=scheduled__2023-09-02T00:00:00+00:00/task_id=insert_into_table permission to 509
[2023-09-03T05:00:44.249+0000] {logging_mixin.py:151} INFO - Failed to change /opt/***/logs/dag_id=dag_with_postgres_operator_v02/run_id=scheduled__2023-09-02T00:00:00+00:00/task_id=insert_into_table permission to 509: [Errno 1] Operation not permitted: '/opt/***/logs/dag_id=dag_with_postgres_operator_v02/run_id=scheduled__2023-09-02T00:00:00+00:00/task_id=insert_into_table'
[2023-09-03T05:00:44.251+0000] {task_command.py:415} INFO - Running <TaskInstance: dag_with_postgres_operator_v02.insert_into_table scheduled__2023-09-02T00:00:00+00:00 [running]> on host 6c82fec646db
[2023-09-03T05:00:44.348+0000] {taskinstance.py:1660} INFO - Exporting env vars: AIRFLOW_CTX_DAG_OWNER='qpsss' AIRFLOW_CTX_DAG_ID='dag_with_postgres_operator_v02' AIRFLOW_CTX_TASK_ID='insert_into_table' AIRFLOW_CTX_EXECUTION_DATE='2023-09-02T00:00:00+00:00' AIRFLOW_CTX_TRY_NUMBER='1' AIRFLOW_CTX_DAG_RUN_ID='scheduled__2023-09-02T00:00:00+00:00'
[2023-09-03T05:00:44.349+0000] {sql.py:274} INFO - Executing: 
            insert into dag_runs (dt, dag_id) values ('2023-09-02', 'dag_with_postgres_operator_v02')
        
[2023-09-03T05:00:44.361+0000] {base.py:73} INFO - Using connection ID 'postgres_localhost' for task execution.
[2023-09-03T05:00:44.373+0000] {base.py:73} INFO - Using connection ID 'postgres_localhost' for task execution.
[2023-09-03T05:00:44.381+0000] {sql.py:418} INFO - Running statement: 
            insert into dag_runs (dt, dag_id) values ('2023-09-02', 'dag_with_postgres_operator_v02')
        , parameters: None
[2023-09-03T05:00:44.398+0000] {taskinstance.py:1943} ERROR - Task failed with exception
Traceback (most recent call last):
  File "/home/airflow/.local/lib/python3.8/site-packages/airflow/providers/common/sql/operators/sql.py", line 280, in execute
    output = hook.run(
  File "/home/airflow/.local/lib/python3.8/site-packages/airflow/providers/common/sql/hooks/sql.py", line 392, in run
    self._run_command(cur, sql_statement, parameters)
  File "/home/airflow/.local/lib/python3.8/site-packages/airflow/providers/common/sql/hooks/sql.py", line 423, in _run_command
    cur.execute(sql_statement)
psycopg2.errors.UniqueViolation: duplicate key value violates unique constraint "dag_runs_pkey"
DETAIL:  Key (dt, dag_id)=(2023-09-02, dag_with_postgres_operator_v02) already exists.

[2023-09-03T05:00:44.416+0000] {taskinstance.py:1400} INFO - Marking task as UP_FOR_RETRY. dag_id=dag_with_postgres_operator_v02, task_id=insert_into_table, execution_date=20230902T000000, start_date=20230903T050044, end_date=20230903T050044
[2023-09-03T05:00:44.438+0000] {standard_task_runner.py:104} ERROR - Failed to execute job 72 for task insert_into_table (duplicate key value violates unique constraint "dag_runs_pkey"
DETAIL:  Key (dt, dag_id)=(2023-09-02, dag_with_postgres_operator_v02) already exists.
; 10451)
[2023-09-03T05:00:44.454+0000] {local_task_job_runner.py:228} INFO - Task exited with return code 1
[2023-09-03T05:00:44.475+0000] {taskinstance.py:2784} INFO - 0 downstream tasks scheduled from follow-on schedule check
